2022-09-23 21:43:39,958 - pyswarms.single.global_best - INFO - Optimize for 100 iters with {'c1': 0.5, 'c2': 0.3, 'w': 0.9}
2022-09-23 21:45:21,342 - pyswarms.single.global_best - INFO - Optimize for 100 iters with {'c1': 0.5, 'c2': 0.3, 'w': 0.9}
2022-09-23 21:50:03,339 - pyswarms.single.global_best - INFO - Optimize for 100 iters with {'c1': 0.5, 'c2': 0.3, 'w': 0.9}
2022-09-23 21:51:40,938 - pyswarms.single.global_best - INFO - Optimize for 100 iters with {'c1': 0.5, 'c2': 0.3, 'w': 0.9}
2022-09-23 22:04:49,487 - pyswarms.single.global_best - INFO - Optimization finished | best cost: 5.493680612526236, best pos: [0.38020392 0.05750891 0.69385938 0.70980003 0.81831161 0.87059704
 0.90135495 0.75593346 0.73534266 0.87073122]
2022-09-23 22:38:44,135 - pyswarms.single.global_best - INFO - Optimize for 100 iters with {'c1': 0.5, 'c2': 0.3, 'w': 0.9}
2022-09-23 23:22:24,283 - pyswarms.single.global_best - INFO - Optimize for 100 iters with {'c1': 0.5, 'c2': 0.3, 'w': 0.9}
2022-09-23 23:35:52,500 - pyswarms.single.global_best - INFO - Optimization finished | best cost: 4.146873979110645, best pos: [ 0.40600782 -0.67501599  0.56060173  0.73526484  0.8822726   1.08250365
  1.08579973  1.06390791  1.05627801  0.96984579]
2022-09-24 00:15:56,139 - pyswarms.single.global_best - INFO - Optimize for 100 iters with {'c1': 0.5, 'c2': 0.3, 'w': 0.9}
2022-09-24 00:17:58,125 - pyswarms.single.global_best - INFO - Optimize for 100 iters with {'c1': 0.5, 'c2': 0.3, 'w': 0.9}
2022-09-24 00:31:10,712 - pyswarms.single.global_best - INFO - Optimization finished | best cost: 3.0369911885505543, best pos: [0.26456432 0.04765916 0.02080087 0.03431577 0.67463673 0.79391515
 0.61178164 0.8123031  0.54771735 0.55623822]
2022-09-24 01:08:46,538 - pyswarms.single.global_best - INFO - Optimize for 1000 iters with {'c1': 0.5, 'c2': 0.3, 'w': 0.9}
2022-09-24 09:11:40,264 - pyswarms.single.global_best - INFO - Optimize for 100 iters with {'c1': 0.5, 'c2': 0.3, 'w': 0.9}
2022-09-24 09:20:22,444 - pyswarms.single.global_best - INFO - Optimize for 100 iters with {'c1': 0.5, 'c2': 0.3, 'w': 0.9}
2022-09-24 09:25:23,208 - pyswarms.single.global_best - INFO - Optimize for 100 iters with {'c1': 0.5, 'c2': 0.3, 'w': 0.9}
2022-09-24 09:25:41,247 - pyswarms.single.global_best - INFO - Optimize for 100 iters with {'c1': 0.5, 'c2': 0.3, 'w': 0.9}
2022-09-24 09:27:25,165 - pyswarms.single.global_best - INFO - Optimize for 100 iters with {'c1': 0.5, 'c2': 0.3, 'w': 0.9}
2022-09-24 09:29:25,447 - pyswarms.single.global_best - INFO - Optimize for 100 iters with {'c1': 0.5, 'c2': 0.3, 'w': 0.9}
2022-09-24 09:42:49,116 - pyswarms.single.global_best - INFO - Optimization finished | best cost: 0.14569616322469328, best pos: [0.         0.         0.05017925 0.19985535 0.64681014 0.90096143
 0.94950517 0.95039481 1.         0.99915579]
2022-09-24 10:54:31,003 - pyswarms.single.global_best - INFO - Optimize for 100 iters with {'c1': 0.5, 'c2': 0.3, 'w': 0.9}
2022-09-24 10:54:56,619 - pyswarms.single.global_best - INFO - Optimize for 100 iters with {'c1': 0.5, 'c2': 0.3, 'w': 0.9}
2022-09-24 10:55:12,913 - asyncio - ERROR - Task was destroyed but it is pending!
task: <Task pending name='Task-2' coro=<Kernel.poll_control_queue() running at /Users/ajshajib/miniforge3/lib/python3.9/site-packages/ipykernel/kernelbase.py:284> wait_for=<Future pending cb=[<TaskWakeupMethWrapper object at 0x113f70fd0>()]> cb=[_chain_future.<locals>._call_set_state() at /Users/ajshajib/miniforge3/lib/python3.9/asyncio/futures.py:391]>
2022-09-24 10:55:26,186 - pyswarms.single.global_best - INFO - Optimize for 100 iters with {'c1': 0.5, 'c2': 0.3, 'w': 0.9}
2022-09-24 10:56:02,651 - pyswarms.backend.generators - ERROR - Bounds and/or init_pos should be of size (10,)
Traceback (most recent call last):
  File "/Users/ajshajib/miniforge3/lib/python3.9/site-packages/pyswarms/backend/generators.py", line 67, in generate_swarm
    raise ValueError("User-defined init_pos is out of bounds.")
ValueError: User-defined init_pos is out of bounds.
2022-09-24 10:56:40,558 - pyswarms.backend.generators - ERROR - Bounds and/or init_pos should be of size (10,)
Traceback (most recent call last):
  File "/Users/ajshajib/miniforge3/lib/python3.9/site-packages/pyswarms/backend/generators.py", line 67, in generate_swarm
    raise ValueError("User-defined init_pos is out of bounds.")
ValueError: User-defined init_pos is out of bounds.
2022-09-24 10:57:00,874 - pyswarms.backend.generators - ERROR - Bounds and/or init_pos should be of size (10,)
Traceback (most recent call last):
  File "/Users/ajshajib/miniforge3/lib/python3.9/site-packages/pyswarms/backend/generators.py", line 67, in generate_swarm
    raise ValueError("User-defined init_pos is out of bounds.")
ValueError: User-defined init_pos is out of bounds.
2022-09-24 10:57:07,664 - pyswarms.backend.generators - ERROR - Bounds and/or init_pos should be of size (10,)
Traceback (most recent call last):
  File "/Users/ajshajib/miniforge3/lib/python3.9/site-packages/pyswarms/backend/generators.py", line 67, in generate_swarm
    raise ValueError("User-defined init_pos is out of bounds.")
ValueError: User-defined init_pos is out of bounds.
2022-09-24 10:58:47,123 - pyswarms.backend.generators - ERROR - Bounds and/or init_pos should be of size (10,)
Traceback (most recent call last):
  File "/Users/ajshajib/miniforge3/lib/python3.9/site-packages/pyswarms/backend/generators.py", line 67, in generate_swarm
    raise ValueError("User-defined init_pos is out of bounds.")
ValueError: User-defined init_pos is out of bounds.
2022-10-02 19:11:38,652 - pyswarms.backend.generators - ERROR - Bounds and/or init_pos should be of size (10,)
Traceback (most recent call last):
  File "/Users/ajshajib/miniforge3/lib/python3.9/site-packages/pyswarms/backend/generators.py", line 67, in generate_swarm
    raise ValueError("User-defined init_pos is out of bounds.")
ValueError: User-defined init_pos is out of bounds.
2022-10-02 19:11:42,278 - pyswarms.backend.generators - ERROR - Bounds and/or init_pos should be of size (10,)
Traceback (most recent call last):
  File "/Users/ajshajib/miniforge3/lib/python3.9/site-packages/pyswarms/backend/generators.py", line 67, in generate_swarm
    raise ValueError("User-defined init_pos is out of bounds.")
ValueError: User-defined init_pos is out of bounds.
